Workbook

Sheet 0_guide
B1: mucho cuidado al copiar datos numericos con comas o puntos
A3: 1 | B3: our_id | C3: Identification number, the same as for the abstract screening
B4: study_type | C4: Categories: (1) remote sensing, (2) palaeoecology, (3) field study, (4) remote sensing and field study and (5) others
B5: study_level | C5: Categories: (1) comunity (focuses on community), (2) species (focuses on individual species) and (3) comunity and species (focuses on community level but also provides specific species measures, for example, pine density). Leave blank if the study does not focus on vegetation
B6: n_fires | C6: Number of fires analysed in the study
B7: revision_date | C7: date the article was reviewed
B8: comments | C8: Any additional relevant notes or observations
A10: 2 | B10: our_id | C10: Identification number, the same as for the abstract screening
B11: fire_id | C11: Identifier for each fire in the study, starting at 1 up to i
B12: fire_date | C12: Fire date in YYYY_MM_DD format. If specific details are missing, use YYYY_MM or YYYY. If the sampling period includes fires with unknown exact dates, record the full range (e.g., 1975-2001)
B13: season | C13: Record the season only if the date provides a year but no month, and explicitly includes a seasonal reference
B14: country | C14: Country or specific study site name
B15: origin_coords | C15: Source of study coordinates. Categories: (1) exact (explicitly stated in the text), (2) mean point (mean point of a range explicitly stated in the text, and, (3) estimated (not explicit; georeferenced based on site descriptions or location).
B16: latitude | C16: Latitude in decimal degrees (World Geodetic System 1984, EPSG: 4326). If there are several coordinates, enter the center point.
B17: longitude | C17: Longitude in decimal degrees (World Geodetic System 1984, EPSG: 4326). If there are several coordinates, enter the centre point.
B18: elevation | C18: Metres above sea level (m a.s.l.). If a range is given, enter the mean altitude. NA if not specified
B19: fire_size | C19: Affected area (ha). NA if not specified
B20: severity | C20: Categories: (1) low, (2) moderate, (3) high, (4) low;moderate, (5) moderate;high and, (6) all. Based on Keeley (2009). If fire severity is not explicitly stated but can be inferred from the description, classify it accordingly (e.g., active crown fire causing total tree mortality = high severity). If it cannot be determined, write NA.
B21: fire_type | C21: single / combined (If the results are given aggregated for many fires)
B22: forest_type | C22: Present prefire forest: Mixed, pine forest, oak forest, etc.
... B25: comments | C25: Any additional relevant notes or observations
A27: 3 | B27: our_id | C27: Identification number, the same as for the abstract screening
B28: response_variable | C28: Reported response variable in the study. Strictly post-fire only; exclude pre-fire measurements and results from unburned plots. Fire severity measurements are excluded because they characterize conditions during the fire event itself, not post-fire recovery responses. If a single response variable combines multiple measurements of the same property in the same units, report each measurement separately rather than aggregating them (e.g., report Na, K, and Ca content individually instead of as exchangeable cations). If a measure is expressed in different units for the same response variable, report both. If the response is adimensional, indicate the range of numerical variation from the reported results.
B29: response_units | C29: The unit in which the measured variable is reported. If its adimensional, report the range in which is measured.
B30: variable_type | C30: Categories: (1) vegetation, (2) soil (including microorganisms and fungii), (3) fauna and (4) others
B31: variable_subtype | C31: Specific classification of the response variable. Categories: (1) diversity, (2) composition, (3) structure and (4) regeneration, (5) physical properties, (6) chemical properties, (7) erosion, (8) interactions and (9) ecosystem services (Gann et al. 2019) (Wortley et al. 2013). Add more categories if necessary but report it in "Changes" shared document via Teams. Also, when it's a spectral response, report in "comments" the interpretation (for structure, composition, greeness, etc.). If you are unsure how to classify a variable, choose it based on the final purpose of the study; in other words, ask yourself what you intend to discover with that measurement.
B32: sampling_type | C32: Plot, transect, etc. For remote sensing, report whether the analysis is conducted at the pixel or plot level.
B33: measure_date | C33: First post-fire sampling date (YYYY_MM_DD). For remote sensing, use the earliest image acquisition date after the fire. Do not use pre-fire dates, even if reported in the study.
B34: season | C34: Record the season only if the date provides a year but no month, and explicitly includes a seasonal reference
B35: moderator_type | C35: Type of moderator variable tested as a potential source of variation in effect size (e.g., water stress, fire severity, years since fire, management, climate). Extract these when explicitly defined in methodology section and also reported in the results. Include variables treated as explanatory factors or predictors. Include predictors used in multivariate analyses (e.g., PCA, GLM). Exclude correlations without explanatory testing. Exclude random effects. Exclude interaction terms. When multiple moderators are reported, separate them with “;” (e.g., fire severity; management).
B36: comments | C36: Any additional relevant notes or observations
A38: 4 | B38: our_id | C38: Identification number, the same as for the abstract screening
B39: reason | C39: Reason for rejection
B40: comments | C40: Any additional relevant notes or observations

Sheet 1_study
A1: our_id | B1: study_type | C1: study_level | D1: n_fires | E1: revision_date | F1: comments | G1: Revisor
A2: 4 | B2: field;remote sensing | C2: community | D2: 1 | G2: Anna
A3: 16 | B3: remote sensing | C3: community | D3: 1 | G3: Anna
A4: 17 | B4: field | C4: community | D4: 1 | G4: Anna
A5: 29 | B5: field | C5: community | D5: 1 | G5: Anna
A6: 78 | B6: field | C6: community | D6: 1 | G6: Anna
A7: 84 | B7: field | C7: community | D7: 4 | G7: Anna
A8: 103 | B8: field | C8: community | D8: 1 | G8: Anna
A9: 111 | B9: field | C9: community | D9: 1 | G9: Anna
A10: 142 | B10: field | C10: community | D10: 2 | G10: Anna
A11: 145 | B11: field | C11: community | D11: 7 | G11: Anna
A12: 152 | B12: remote sensing | C12: community | D12: 2 | G12: Anna
A13: 168 | B13: remote sensing | C13: community | D13: 2 | G13: Anna
... A46: 523 | B46: field | C46: community | D46: 3 | G46: Anna
A47: 532 | B47: field;remote sensing | C47: community | D47: NA | G47: Anna
A48: 533 | B48: field | C48: community | D48: 9 | G48: Anna
A49: 550 | B49: field;remote sensing | C49: community | D49: 1 | G49: Anna
A50: 553 | B50: field | C50: community | D50: 5 | G50: Anna
A51: 561 | B51: field | C51: community | D51: 1 | G51: Anna
A52: 566 | B52: field | C52: community | D52: 1 | G52: Anna
A53: 597 | B53: palaeoecology | C53: species | D53: 2 | G53: Anna
A54: 603 | B54: field | C54: species | D54: 1 | G54: Anna
A55: 604 | B55: field | C55: community | D55: 2 | G55: Anna
A56: 612 | B56: palaeoecology | C56: community | D56: 22 | G56: Anna
A57: 617 | B57: remote sensing | C57: community | D57: NA | G57: Anna
A58: 621 | B58: field | C58: community | D58: 1 | G58: Anna
A59: 10 | B59: remote sensing | C59: community | D59: 1 | G59: Patri
A60: 12 | B60: field | C60: community | D60: 14 | G60: Patri
A61: 22 | B61: field | C61: community | D61: 1 | G61: Patri
A62: 32 | B62: field | C62: species | D62: 1 | G62: Patri
A63: 52 | B63: field | C63: species | D63: 5 | G63: Patri
A64: 65 | B64: palaeoecology | C64: species | D64: NA | G64: Patri
A65: 75 | B65: field | C65: species | D65: 2 | G65: Patri
A66: 631 | B66: field | C66: species | D66: 3 | G66: Anna
A67: 634 | B67: field | C67: community | D67: NA | G67: Anna
A68: 647 | B68: field | C68: community | D68: 1 | G68: Anna
A69: 674 | B69: field;remote sensing | C69: species | D69: 1 | G69: Anna
A70: 683 | B70: field | C70: community;species | D70: 2 | G70: Anna
A71: 687 | B71: field | C71: community;species | D71: NA | G71: Anna
A72: 708 | B72: field;remote sensing | C72: community | D72: 15 | G72: Anna
...

Sheet 1_study_resumen
A1: tipo estudio | B1: recuento
A2: field | B2: =COUNTIF('1_study'!B2:B288, "field") -> 211 | E2: me quedo con las 3
A3: remote sensing | B3: =COUNTIF('1_study'!B3:B288, "remote sensing") -> 33
A4: field;remote sensing | B4: =COUNTIF('1_study'!B4:B288, "field;remote sensing") -> 39
A5: palaeoecology | B5: =COUNTIF('1_study'!B5:B288, "palaeoecology") -> 3
B6: =SUM(B2:B5) -> 286
L10: ST
K11: SL | L11: field | M11: rs | N11: field;rs | Q11: total estudios | R11: =SUM(B2:B4) -> 283
K12: comm | L12: 32 | M12: 22 | N12: 13
K13: comm;sp | L13: 12 | M13: 0 | N13: 3
K14: sp | L14: 23 | M14: 0 | N14: 2
I17: % global | K17: Tipo de estudio | O17: Nivel de estudio | P17: Tipo de estudio
J18: Nivel de estudio | K18: Campo | L18: Teledetección | M18: Campo + Teledetección | P18: Campo | Q18: Teledetección | R18: Campo + Teledetección | S18: Paleoecología
J19: Comunidad | K19: 31.85 | L19: 17.04 | M19: 10.37 | O19: Comunidad | P19: 31.85 | Q19: 17.04 | R19: 10.37
J20: Comunidad + Especies | K20: 14.07 | L20: 0.74 | M20: 2.2 | O20: Comunidad + Especies | P20: 14.07 | Q20: 0.74 | R20: 2.2
J21: Especies | K21: 21.48 | L21: 0 | M21: 2.2 | O21: Especies | P21: 21.48 | Q21: 0 | R21: 2.2
I23: % portipoestudio | K23: Tipo de estudio
J24: Nivel de estudio | K24: Campo | L24: Teledetección | M24: Campo + Teledetección
J25: Comunidad | K25: 47.761194 | L25: 100 | M25: 72.222222
J26: Comunidad + Especies | K26: 17.910448 | L26: 0 | M26: 16.666667
J27: Especies | K27: 34.328358 | L27: 0 | M27: 11.111111 | O27: study_type
O28: study_level field field;remote sensing palaeoecology remote sensing
O29: community 27.8026906 8.9686099 0.4484305 13.0044843
A30: study_type | B30: study_level | C30: n_fires | O30: community;species 19.7309417 4.0358744 0.0000000 0.4484305
A31: remote sensing | B31: community | C31: 1 | O31: species 23.7668161 0.8968610 0.8968610 0.0000000
A32: remote sensing | B32: community | C32: 2 | E32: =AVERAGE(C31:C38,C41,C44:C45,C47:C49,C51,C53:C57,C59:C63) -> 2.2
A33: remote sensing | B33: community | C33: 2 | E33: =AVERAGE(C31:C39,C41:C42,C44:C45,C47:C49,C51,C53:C57,C59:C63) -> 172.55556 | J33: study_type
A34: remote sensing | B34: community | C34: 1 | J34: study_level field remote sensing field;remote sensing
A35: remote sensing | B35: community | C35: 3 | J35: community 31.8518519 17.0370370 10.3703704
A36: remote sensing | B36: community | C36: 2 | J36: community;species 14.0740741 0.7407407 2.2222222
A37: remote sensing | B37: community | C37: 2 | J37: species 21.4814815 0.0000000 2.2222222
A38: remote sensing | B38: community | C38: 1
A39: remote sensing | B39: community | C39: 4131
A40: remote sensing | B40: community | C40: NA
A41: remote sensing | B41: community | C41: 1
A42: remote sensing | B42: community | C42: 473
A43: remote sensing | B43: community | C43: NA
A44: remote sensing | B44: community | C44: 1
A45: remote sensing | B45: community | C45: 1
A46: remote sensing | B46: community | C46: NA
...

Sheet 2_fire
A1: our_id | B1: fire_id | C1: fire_date | D1: season | E1: country | F1: origin_coords | G1: latitude | H1: longitude | I1: elevation | J1: fire_size | K1: severity | L1: fire_type | M1: forest_type | N1: forest_details | O1: postfire_management | P1: comments
A2: 4 | B2: 1 | C2: 2016_01_06 | D2: summer | E2: Australia | F2: exact | G2: -32.15 | H2: 116.8 | I2: 248 | J2: 69165 | K2: high | L2: single | M2: eucalypt forest | N2: dry sclerophyll forest domi-nated by Eucalyptus marginata | O2: none
A3: 16 | B3: 1 | C3: 2017_10_15 | D3: autumn | E3: Portugal | F3: mean point | G3: 40.333333 | H3: -7.85 | I3: 400 | J3: 7600 | K3: high | L3: single | M3: pine forest | N3: dominated by Pinus pinaster | O3: none
A4: 16 | B4: 1 | C4: 2017_10_15 | D4: autumn | E4: Portugal | F4: mean point | G4: 40.333333 | H4: -7.85 | I4: 400 | J4: 7600 | K4: high | L4: single | M4: broadleaves forest | N4: The forest is mainly composed of pine trees (43%) and broadleaf trees (13%). Pinus pinaster is cultivated. There is Eucalyptus globulus as exotic specie that is 1% of the area. On the other hand, invasive forest species, like Acacia dealbata and Ailanthus altissima, occupy 10% of the area | O4: none
A5: 17 | B5: 1 | C5: 2015_09_12 | D5: summer | E5: EEUU | F5: exact | G5: 38.83528 | H5: -122.70148 | I5: =(1050+1113)/2 -> 1081.5 | J5: 30700 | K5: high | L5: single | M5: pine forest | N5: dominated by Pinus ponderosa | O5: erosion control
A6: 17 | B6: 1 | C6: 2015_09_12 | D6: summer | E6: EEUU | F6: exact | G6: 38.83528 | H6: -122.70148 | I6: =(1050+1113)/2 -> 1081.5 | J6: 30700 | K6: high | L6: single | M6: pine forest | N6: dominated by Pinus ponderosa | O6: silvicultural
A7: 29 | B7: 1 | C7: 1994_07_05 | D7: summer | E7: Spain | F7: estimated | G7: 41.773889 | H7: 2.9280556 | I7: =(190+250)/2 -> 220 | J7: 55 | K7: NA | L7: single | M7: pine forest | N7: dominated by Pinus pinaster | O7: erosion control
A8: 29 | B8: 1 | C8: 1994_07_05 | D8: summer | E8: Spain | F8: estimated | G8: 41.773889 | H8: 2.9280556 | I8: =(190+250)/2 -> 220 | J8: 55 | K8: NA | L8: single | M8: cork oak forest | N8: dominated by Quercus suber | O8: erosion control
A9: 29 | B9: 1 | C9: 1994_07_05 | D9: summer | E9: Spain | F9: estimated | G9: 41.773889 | H9: 2.9280556 | I9: =(190+250)/2 -> 220 | J9: 55 | K9: NA | L9: single | M9: pine forest | N9: dominated by Pinus pinaster | O9: reforestation
A10: 29 | B10: 1 | C10: 1994_07_05 | D10: summer | E10: Spain | F10: estimated | G10: 41.773889 | H10: 2.9280556 | I10: =(190+250)/2 -> 220 | J10: 55 | K10: NA | L10: single | M10: cork oak forest | N10: dominated by Quercus suber | O10: reforestation
A11: 78 | B11: 1 | C11: 1989_08 | D11: summer | E11: Greece | F11: mean point | G11: 40.08 | H11: 23.8 | I11: NA | J11: NA | K11: NA | L11: single | M11: pine forest | N11: dominated by Pinus halepensis | O11: none
A12: 84 | B12: 1 | C12: 1978 | E12: Spain | F12: exact | G12: 39.318 | H12: -0.8947 | I12: =(420+400+610+450+475)/5 -> 471 | J12: >500 | K12: NA | L12: combined | M12: pine forest | N12: dominated by Pinus halepensis | O12: none | P12: origin of coordinates is in a supplementary table, out of the article
A13: 84 | B13: 2 | C13: 1979 | E13: Spain | F13: exact | G13: 38.913 | H13: -0.817 | I13: =(806+800+530+806)/4 -> 735.5 | J13: >500 | K13: NA | L13: combined | M13: pine forest | N13: dominated by Pinus halepensis | O13: none | P13: origin of coordinates is in a supplementary table, out of the article
A14: 84 | B14: 3 | C14: 1979 | E14: Spain | F14: exact | G14: 38.803611 | H14: -0.56777778 | I14: 630 | J14: >500 | K14: NA | L14: combined | M14: pine forest | N14: dominated by Pinus halepensis | O14: none | P14: origin of coordinates is in a supplementary table, out of the article
A15: 84 | B15: 4 | C15: 1981 | E15: Spain | F15: exact | G15: 38.803611 | H15: -0.56777778 | I15: 630 | J15: >500 | K15: NA | L15: combined | M15: pine forest | N15: dominated by Pinus halepensis | O15: none | P15: origin of coordinates is in a supplementary table, out of the article
A16: 84 | B16: 5 | C16: 1984 | E16: Spain | F16: exact | G16: 38.913 | H16: -0.817 | I16: =(806+800+530+806)/4 -> 735.5 | J16: >500 | K16: NA | L16: combined | M16: pine forest | N16: dominated by Pinus halepensis | O16: none | P16: origin of coordinates is in a supplementary table, out of the article
A17: 84 | B17: 6 | C17: 1985 | E17: Spain | F17: exact | G17: 38.913 | H17: -0.817 | I17: =(806+800+530+806)/4 -> 735.5 | J17: >500 | K17: NA | L17: combined | M17: pine forest | N17: dominated by Pinus halepensis | O17: none | P17: origin of coordinates is in a supplementary table, out of the article
A18: 84 | B18: 7 | C18: 1991 | E18: Spain | F18: exact | G18: 38.675 | H18: -0.09104 | I18: =(340+445+300+415)/4 -> 375 | J18: >500 | K18: NA | L18: combined | M18: pine forest | N18: dominated by Pinus halepensis | O18: none | P18: origin of coordinates is in a supplementary table, out of the article
A19: 84 | B19: 8 | C19: 1991 | E19: Spain | F19: exact | G19: 39.318 | H19: -0.8947 | I19: =(420+400+610+450+475)/5 -> 471 | J19: >500 | K19: NA | L19: combined | M19: pine forest | N19: dominated by Pinus halepensis | O19: none | P19: origin of coordinates is in a supplementary table, out of the article
A20: 84 | B20: 9 | C20: 1994 | E20: Spain | F20: exact | G20: 38.913 | H20: -0.817 | I20: =(806+800+530+806)/4 -> 735.5 | J20: >500 | K20: NA | L20: combined | M20: pine forest | N20: dominated by Pinus halepensis | O20: none | P20: origin of coordinates is in a supplementary table, out of the article
A21: 84 | B21: 10 | C21: 1994 | E21: Spain | F21: exact | G21: 38.803611 | H21: -0.56777778 | I21: 630 | J21: >500 | K21: NA | L21: combined | M21: pine forest | N21: dominated by Pinus halepensis | O21: none | P21: origin of coordinates is in a supplementary table, out of the article
A22: 84 | B22: 11 | C22: 1999 | E22: Spain | F22: exact | G22: 38.913 | H22: -0.817 | I22: =(806+800+530+806)/4 -> 735.5 | J22: >500 | K22: NA | L22: combined | M22: pine forest | N22: dominated by Pinus halepensis | O22: none | P22: origin of coordinates is in a supplementary table, out of the article
A23: 84 | B23: 12 | C23: 2003 | E23: Spain | F23: exact | G23: 38.675 | H23: -0.09104 | I23: =(340+445+300+415)/4 -> 375 | J23: >500 | K23: NA | L23: combined | M23: pine forest | N23: dominated by Pinus halepensis | O23: none | P23: origin of coordinates is in a supplementary table, out of the article
A24: 84 | B24: 13 | C24: 2010 | E24: Spain | F24: exact | G24: 38.803611 | H24: -0.56777778 | I24: 630 | J24: >500 | K24: NA | L24: combined | M24: pine forest | N24: dominated by Pinus halepensis | O24: none | P24: origin of coordinates is in a supplementary table, out of the article
A25: 84 | B25: 14 | C25: 2012 | E25: Spain | F25: exact | G25: 39.318 | H25: -0.8947 | I25: =(420+400+610+450+475)/5 -> 471 | J25: >500 | K25: NA | L25: combined | M25: pine forest | N25: dominated by Pinus halepensis | O25: none | P25: origin of coordinates is in a supplementary table, out of the article
A26: 84 | B26: 15 | C26: 2016 | E26: Spain | F26: exact | G26: 38.675 | H26: -0.09104 | I26: =(340+445+300+415)/4 -> 375 | J26: >500 | K26: NA | L26: combined | M26: pine forest | N26: dominated by Pinus halepensis | O26: none | P26: origin of coordinates is in a supplementary table, out of the article
A27: 103 | B27: 1 | C27: 2005_09 | E27: Spain | F27: mean point | G27: 36.953333 | H27: -3.4933333 | I27: =(1477+2053)/2 -> 1765 | J27: 1300 | K27: high | L27: single | M27: pine forest | N27: P. pinaster, P. nigra, P. sylvestris in order of increasing elevation | O27: silvicultural
A28: 111 | B28: 1 | C28: 2012_07 | D28: summer | E28: Spain | F28: estimated | G28: 38.393 | H28: -1.682 | I28: 500 | J28: 6500 | K28: high | L28: single | M28: pine forest | N28: dominated by Pinus halepensis | O28: erosion control
A29: 142 | B29: 1 | C29: 1994 | D29: summer | E29: Spain | F29: exact | G29: 38.333333 | H29: -2.3333333 | I29: 1010 | J29: 14000 | K29: NA | L29: single | M29: pine forest | N29: dominated by Pinus halepensis | O29: silvicultural;erosion control
A30: 142 | B30: 2 | C30: 1994 | D30: summer | E30: Spain | F30: exact | G30: 38.266667 | H30: -1.6333333 | I30: 325 | J30: 30000 | K30: NA | L30: single | M30: pine forest | N30: dominated by Pinus halepensis | O30: silvicultural;erosion control
A31: 145 | B31: 1 | C31: 1979 | E31: Turkey | F31: mean point | G31: 36.9 | H31: 28.1 | I31: 101 | J31: NA | K31: NA | L31: combined | M31: pine forest | N31: dominated by Pinus brutia | O31: none
A32: 145 | B32: 2 | C32: 1989 | E32: Turkey | F32: mean point | G32: 36.9 | H32: 28.1 | I32: 101 | J32: NA | K32: NA | L32: combined | M32: pine forest | N32: dominated by Pinus brutia | O32: none
A33: 145 | B33: 3 | C33: 1995 | E33: Turkey | F33: mean point | G33: 36.9 | H33: 28.1 | I33: 101 | J33: NA | K33: NA | L33: combined | M33: pine forest | N33: dominated by Pinus brutia | O33: none
A34: 145 | B34: 4 | C34: 1996 | E34: Turkey | F34: mean point | G34: 36.9 | H34: 28.1 | I34: 101 | J34: NA | K34: NA | L34: combined | M34: pine forest | N34: dominated by Pinus brutia | O34: none
A35: 145 | B35: 5 | C35: 1997 | E35: Turkey | F35: mean point | G35: 36.9 | H35: 28.1 | I35: 101 | J35: NA | K35: NA | L35: combined | M35: pine forest | N35: dominated by Pinus brutia | O35: none
A36: 145 | B36: 6 | C36: 1999 | E36: Turkey | F36: mean point | G36: 36.9 | H36: 28.1 | I36: 101 | J36: NA | K36: NA | L36: combined | M36: pine forest | N36: dominated by Pinus brutia | O36: none
A37: 145 | B37: 7 | C37: 2002 | E37: Turkey | F37: mean point | G37: 36.9 | H37: 28.1 | I37: 101 | J37: NA | K37: NA | L37: combined | M37: pine forest | N37: dominated by Pinus brutia | O37: none
A38: 152 | B38: 1 | C38: 1966_08 | D38: summer | E38: Spain | F38: estimated | G38: 40.460933 | H38: -4.269 | I38: 800 | J38: 790 | K38: NA | L38: single | M38: pine forest | N38: dominated by Pinus pinaster | O38: reforestation
A39: 152 | B39: 2 | C39: 1999_08 | D39: summer | E39: Spain | F39: estimated | G39: 40.620678 | H39: -4.152 | I39: 1340 | J39: 425 | K39: NA | L39: single | M39: pine forest | N39: dominated by Pinus sylvestris | O39: reforestation
A40: 168 | B40: 1 | C40: 2000 | E40: Algeria | F40: mean point | G40: 36.3867 | H40: 0.966 | I40: =(13+867)/2 -> 440 | J40: 5000 | K40: low | L40: single | M40: pine forest | N40: dominated by Pinus halepensis | O40: none
...

Sheet 2_fire_resumen

Sheet 3_measures
A1: our_id | B1: response_variable | C1: response_units | D1: variable_type | E1: variable_subtype | F1: sampling_type | G1: measure_date | H1: season | I1: moderator_type | J1: comments
A2: 4 | B2: QMD (quadratic mean diameter) | C2: cm | D2: vegetation | E2: structure | F2: plot | G2: 2017_01_06 | I2: fire severity;drought probability
A3: 4 | B3: Stem density | C3: stems / ha | D3: vegetation | E3: regeneration | F3: plot | G3: 2017_01_06 | I3: fire severity;drought probability
A4: 4 | B4: Live canopy height | C4: m | D4: vegetation | E4: structure | F4: plot | G4: 2017_01_06 | I4: fire severity;drought probability
A5: 4 | B5: Stem mortality | C5: p. (0-1) | D5: vegetation | E5: regeneration | F5: plot | G5: 2017_01_06 | I5: fire severity;drought probability
A6: 4 | B6: Resprouting stems | C6: p. (0-1) | D6: vegetation | E6: regeneration | F6: plot | G6: 2017_01_06 | I6: fire severity;drought probability
A7: 4 | B7: Fine woody debris | C7: t / ha | D7: vegetation | E7: structure | F7: plot | G7: 2017_01_06 | I7: fire severity;drought probability
A8: 4 | B8: Stem diameter (DBH) | C8: cm | D8: vegetation | E8: structure | F8: plot | G8: 2017_01_06 | I8: fire severity;drought probability
A9: 4 | B9: Stem survival | C9: p. (0-1) | D9: vegetation | E9: regeneration | F9: plot | G9: 2017_01_06 | I9: fire severity;drought probability;tree species;tree cross-sectional area;stem size
A10: 16 | B10: NDVI | C10: -1 to +1 | D10: vegetation | E10: spectral response | F10: remote sensing | G10: 2017_09_28 | I10: gully morphology (width, plan area);topography (ruggeness index, altitude, slope, curvature, flow accumulation);fire severity;time | J10: spectral response refered to regeneration
A11: 17 | B11: sediment yield | C11: Mg / ha · year | D11: soil | E11: erosion | F11: plots | G11: 2016_06 | I11: se_management type;ground cover;precipitation (depth, intensity);canopy closure;time
A12: 17 | B12: ground cover | C12: % | D12: vegetation | E12: structure | F12: plots | G12: 2016_06 | I12: se_management type;time | J12: also could be soil subtype because groundcover classes are: bare soil, wood, vegetation
A13: 17 | B13: canopy closure | C13: % | D13: vegetation | E13: structure | F13: plots | G13: 2016_06 | I13: se_management type;time
A14: 17 | B14: bulk density | C14: g / cm3 | D14: soil | E14: physical properties | F14: plots | G14: 2016_06 | I14: soil depth;se_management type;time
A15: 17 | B15: Hydraulic conductivity (Kfs) | C15: mm / hr | D15: soil | E15: physical properties | F15: plots | G15: 2016_06 | I15: se_management type;time
A16: 17 | B16: soil water repellency | C16: s | D16: soil | E16: physical properties | F16: plots | G16: 2016_06 | I16: se_management type;time
A17: 29 | B17: species composition | C17: nº species | D17: vegetation | E17: composition | F17: transects | G17: 1994_07 | I17: NA
A18: 29 | B18: reproductive strategy | C18: G, R | D18: vegetation | E18: composition | F18: transects | G18: 1994_07 | I18: NA
A19: 29 | B19: height class | C19: % | D19: vegetation | E19: regeneration | F19: transects | G19: 1994_07 | I19: fire intensity
A20: 29 | B20: Height class | C20: cm | D20: vegetation | E20: structure | F20: transects | G20: 1994_07 | I20: fire intensity
A21: 29 | B21: recovery of soil cover | C21: % | D21: vegetation | E21: structure | F21: transects | G21: 1994_07 | I21: fire intensity
A22: 78 | B22: diversity (Berger-Parker index) | C22: 0-5 | D22: vegetation | E22: diversity | F22: plots;transects | G22: 1990_09 | I22: soil type;time
A23: 78 | B23: eveness(Camargo's index) | C23: 0-1 | D23: vegetation | E23: diversity | F23: plots;transects | G23: 1990_09 | I23: soil type;time
A24: 78 | B24: relative abundance | C24: nº individuals | D24: vegetation | E24: composition | F24: plots;transects | G24: 1990_09 | I24: soil type;time;species rank
A25: 84 | B25: multifunctionality | C25: 0-1,25 | D25: others | E25: ecosystem services | F25: plots;transects | G25: 1978 | I25: fire recurrence;TSLF (time since long fire)
A26: 84 | B26: biodiversity conservation | C26: 0-1,25 | D26: others | E26: ecosystem services | F26: plots;transects | G26: 1978 | I26: fire recurrence;TSLF (time since long fire) | J26: ecosystem service of suport
A27: 84 | B27: food production | C27: 0-1,25 | D27: others | E27: ecosystem services | F27: plots;transects | G27: 1978 | I27: fire recurrence;TSLF (time since long fire) | J27: ecosystem service of provision
A28: 84 | B28: carbon sequestration | C28: 0-1,25 | D28: others | E28: ecosystem services | F28: plots;transects | G28: 1978 | I28: fire recurrence;TSLF (time since long fire) | J28: ecosystem service of regulation
A29: 84 | B29: disturbance regulation | C29: 0-1,25 | D29: others | E29: ecosystem services | F29: plots;transects | G29: 1978 | I29: fire recurrence;TSLF (time since long fire) | J29: ecosystem service of regulation
A30: 84 | B30: supporting services | C30: 0-1,25 | D30: others | E30: ecosystem services | F30: plots;transects | G30: 1978 | I30: fire recurrence;TSLF (time since long fire) | J30: ecosystem service of suport
A31: 84 | B31: dead fuel bulk density | C31: 0-1,3 | D31: soil | E31: physical properties | F31: plots;transects | G31: 1978 | I31: fire recurrence
A32: 103 | B32: snag basal diameter | C32: cm | D32: vegetation | E32: structure | F32: plots;subplots | G32: 2006_02 | I32: s_management type;elevation;
A33: 103 | B33: snag fall rate | C33: % | D33: vegetation | E33: ecological processes | F33: plots;subplots | G33: 2006_02 | I33: s_management type;time
A34: 103 | B34: snag retention time | C34: days | D34: vegetation | E34: ecological processes | F34: plots;subplots | G34: 2006_02 | I34: silvicultural treatment;elevation;snag basal diameter
A35: 111 | B35: waste decomposition | C35: 0-1 | D35: others | E35: ecosystem services | F35: plots;transects;grid squares | G35: 2012_10 | I35: e_management type;soil properties;species richness;ground cover;time | J35: ecosystem service of suport
A36: 111 | B36: water cycle | C36: 0-1 | D36: others | E36: ecosystem services | F36: plots;transects;grid squares | G36: 2012_10 | I36: e_management type;soil properties;species richness;ground cover;time | J36: ecosystem service of suport
A37: 111 | B37: nutrient cycling | C37: 0-1 | D37: others | E37: ecosystem services | F37: plots;transects;grid squares | G37: 2012_10 | I37: e_management type;soil properties;species richness;ground cover;time | J37: ecosystem service of suport
A38: 111 | B38: climate regulation | C38: 0-1 | D38: others | E38: ecosystem services | F38: plots;transects;grid squares | G38: 2012_10 | I38: e_management type;soil properties;species richness;ground cover;time | J38: ecosystem service of regulation
A39: 111 | B39: biomass production | C39: 0-1 | D39: others | E39: ecosystem services | F39: plots;transects;grid squares | G39: 2012_10 | I39: e_management type;soil properties;species richness;ground cover;time | J39: ecosystem service of provision
A40: 111 | B40: multifunctionality | C40: 0-1 | D40: others | E40: ecosystem services | F40: plots;transects;grid squares | G40: 2012_10 | I40: e_management type;soil properties;species richness;ground cover;time
...

Sheet 3_measures_resumen
A1: Tipo de variable respuesta | B1: Recuento | C1: % | I1: moderator_type | J1: n_papers | K1: Moderator group | O1: Big groups | P1: subtypes
A2: vegetación | B2: =COUNTIF('3_measures'!D:D, "vegetation") -> 955 | C2: =B2/$B$6 -> 0.47869674 | J2: 8 | O2: fire | P2: years after fire
A3: suelo | B3: =COUNTIF('3_measures'!D:D, "soil") -> 787 | C3: =B3/$B$6 -> 0.39448622 | I3: Basal Area Increment | J3: 1 | K3: vegetation | O3: vegetation
A4: fauna | B4: =COUNTIF('3_measures'!D:D, "fauna") -> 194 | C4: =B4/$B$6 -> 0.097243108 | I4: Fire type (crown vs. understory) | J4: 1 | K4: fire | O4: topography
A5: otras | B5: =COUNTIF('3_measures'!D:D, "others") -> 59 | C5: =B5/$B$6 -> 0.029573935 | I5: NBR disturbance | J5: 1 | K5: fire | O5: management
B6: =SUM(B2:B5) -> 1995 | C6: =B6/$B$6 -> 1 | I6: Regenerative functional traits | J6: 5 | K6: vegetation
I7: SOM | J7: 4
I8: Soil layer | J8: 5
I9: TOC | J9: 3
I10: Thornthwaite index | J10: 4
I11: VARI index | J11: 1
I12: annual herbs) | J12: 2
I13: aspect | J13: 14 | K13: topography
I14: aspects | J14: 2 | K14: topography
I15: available phosphorus | J15: 4
I16: bark thickness | J16: 1
I17: basal area of Pinus halepensis | J17: 1
I18: basal area of Quercus ilex | J18: 1
I19: basal area of Quercus pubescens | J19: 1
I20: burn severity | J20: 4
I21: burned area | J21: 1
I22: burned/unburned | J22: 2
I23: cone age | J23: 4
I24: cone type | J24: 4
I25: distance from the unburned age | J25: 1
I26: distance to closest reproductive tree | J26: 1
... I28: electrical conductivity | J28: 4
I29: elevation) | J29: 1 | K29: topography
I30: fire id | J30: 1 | K30: fire
I31: fire occurrence | J31: 4 | K31: fire
I32: fire plot type | J32: 10 | K32: fire
I33: fire recurrence | J33: 14 | K33: fire
I34: fire return interval | J34: 1 | K34: fire
I35: fire severity | J35: 21 | K35: fire
I36: fire type (crown vs surface) | J36: 3 | K36: fire
I37: forest area | J37: 1
I38: land slope | J38: 1
I39: land use | J39: 5
I40: landscape type | J40: 1
I41: life form (woody, perennial herbs | J41: 2
...

Sheet 4_Exclusion
A1: our_id | B1: reason | C1: comments | D1: excludetype
A2: 31 | B2: centered in remote sensing prediction models efficiency | D2: C4
A3: 36 | B3: book chapter | D3: C1
A4: 37 | B4: book chapter | D4: C1 | F4: recompte | G4: %
A5: 45 | B5: conference paper | D5: C1 | F5: =COUNTIF(D:D,"C1") -> 16 | G5: =F5/$F$10 -> 0.30769231
A6: 86 | B6: predictive models | D6: C4 | F6: =COUNTIF(D:D,"C2") -> 19 | G6: =F6/$F$10 -> 0.36538462
A7: 88 | B7: experiment in controlled conditions | D7: C4 | F7: =COUNTIF(D:D,"C3") -> 1 | G7: =F7/$F$10 -> 0.019230769
A8: 46 | B8: it does not present postfire responses, about diverse degradation factors | D8: C5 | F8: =COUNTIF(D:D,"C4") -> 14 | G8: =F8/$F$10 -> 0.26923077
A9: 108 | B9: it is in non mediterranean environment | D9: C3 | F9: =COUNTIF(D:D,"C5") -> 2 | G9: =F9/$F$10 -> 0.038461538
A10: 135 | B10: not a recovery context, measures in an stablished forest about sivicultural treatments | D10: C2 | F10: =SUM(F5:F9) -> 52
A11: 140 | B11: experiment in controlled conditions | D11: C4
A12: 163 | B12: centered in thinning effects, not postfire effects | D12: C2
A13: 181 | B13: book chapter | D13: C1
A14: 194 | B14: prescribed burning and response of a a grass | D14: C2
A15: 202 | B15: effects of waste compost treatment to burn soils | D15: C2
A16: 205 | B16: shrubby and herbaceus context, not forest | D16: C2
A17: 246 | B17: centered in quarry rehabilitations and no forest context | D17: C2
A18: 656 | B18: conference paper | D18: C1
A19: 693 | B19: proceedings paper | D19: C1
A20: 770 | B20: proceedings paper | D20: C1
A21: 998 | B21: conference paper | D21: C1
A22: 1019 | B22: proceedings paper | D22: C1
... A25: 279 | B25: it doesn't mention specific fires | D25: C5
A26: 84 | B26: Duda - incluye incendios experimentales aunque es minoria
A27: 307 | B27: Study conducted in an established Arbutus unedo forest, not in a recovery context | D27: C6
A28: 321 | B28: Predictive models and centered in evaluating remote sensing efficiency | D28: C4
A29: 341 | B29: centered in acorn productivity, not in postfire response. In an established recovered postfire forest | D29: C6
A30: 404 | B30: the 90% of the study area is scrubland | D30: C2
A31: 410 | B31: lacks specific fire past events and precise dates, more regional and broad scale
A32: 411 | B32: lacks specific fire past events and precise dates, more regional and broad scale
A33: 513 | B33: main vegetation is shrubland and agricultural, forest type is not distinguished in results | D33: C2
A34: 539 | B34: centered in management implications and not field work | D34: C2
A35: 568 | B35: it applies predictive models and machine learning algorithm to study postfire recovery | D35: C4
A36: 52 | B36: Duda - son parcelas quemadas, pero lo he registrado igual
A37: 666 | B37: palaeoecology but not centered in fires, it does not identify fire episodes | D37: C6
A38: 675 | B38: it applies random forest model to predict factor effects on vegetation recovery | D38: C4
A39: 737 | B39: same article as 724
A40: 746 | B40: Duda - articulo en italiano
A41: 843 | B41: The studied community consists of codominant shrublands and forests; results were not differentiated by vegetation type | D41: C2
A42: 957 | B42: Duda - articulo en francés
...

Sheet Aux
A1: study_type | B1: study_level | C1: origin_coords | D1: severity | E1: postfire_management | F1: fire_type | G1: variable_type | H1: variable_subtype | J1: Apuntes
A2: remote sensing | B2: species | C2: exact | D2: low | E2: silvicultural | F2: single | G2: vegetation | H2: diversity
A3: palaeoecology | B3: community | C3: mean point | D3: moderate | E3: reforestation | F3: combined | G3: soil | H3: composition | J3: Abundancia total | K3: Nº individuos totales de la especie. Indica estructura de la comunidad.
A4: field | B4: community;species | C4: estimated | D4: high | E4: erosion control | G4: fauna | H4: structure | J4: Abundancia relativa | K4: proporción de una especie o taxón respecto a todas las especies o taxones contenidos en un sitio. Indica que tan común o rara es la especie en la comunidad. Es una variable de composición
A5: field;remote sensing | B5: NA | D5: low;moderate | E5: none | G5: others | H5: regeneration | J5: Eveness index | K5: Species evenness describes the commonness or rarity of a species; it requires knowing the abundance of each species relative to those of the other species within the community.
A6: others | D6: moderate;high | E6: silvicultural;erosion control | H6: physical properties
D7: low;high | E7: erosion control; reforestation | H7: chemical properties
D8: all | E8: silvicultural; reforestation | H8: biological properties
D9: NA | E9: amendments | H9: ecological processes
E10: silvicultural;erosion control;reforestation | H10: erosion
E11: silvicultural;amendments | H11: interactions
E12: NA | H12: reproduction
E13: herbivore exclusion | H13: spectral response
E14: silvicultural;none | H14: others
H15: landscape
H16: ecosystem services | I16: *for ecosystem services, in comments
H17: supporting services
H18: provisioning services
H19: regulating services
H20: cultural services
H21: functional traits
